<mujoco model="Skydio X2">

  <extension>
    <plugin plugin="mujoco.elasticity.cable"/>
  </extension>
  
  <compiler autolimits="true" assetdir="assets"/>

  <option timestep="0.01" density="1.225" viscosity="1.8e-5"/>

  <default>
    <default class="x2">
      <geom mass="0"/>
      <motor ctrlrange="0 13"/>
      <mesh scale="0.01 0.01 0.01"/>
      
      <default class="visual">
        <geom group="2" type="mesh" contype="0" conaffinity="0"/>
      </default>
      
      <default class="collision">
        <geom group="3" type="box"/>
        
        <default class="rotor">
          <geom type="ellipsoid" size=".13 .13 .01"/>
        </default>
        
      </default>
      <site group="5"/>
    </default>
    

  </default>

  <asset>
    <texture type="2d" file="X2_lowpoly_texture_SpinningProps_1024.png"/>
    <material name="phong3SG" texture="X2_lowpoly_texture_SpinningProps_1024"/>
    <material name="invisible" rgba="0 0 0 0"/>

    <mesh class="x2" file="X2_lowpoly.obj"/>
  </asset>

  <worldbody>
    <light name="spotlight" mode="targetbodycom" target="x2" pos="0 -1 2"/>
    
    <body name="load1" pos="0 0 0.425">
	    <geom name="load1"  rgba="0.8 0.8 0.1 1" size="0.3525 0.298 0.325" type="box" mass="0.815"/>
	    <joint name="cable_1e" type="hinge" pos="-0.115 -0.09 0.1625"/>
	    <joint name="cable_2e" type="hinge" pos="0.115 -0.09 0.1625"/>
	    <joint name="cable_3e" type="hinge" pos="0.115 0.09 0.1625"/>
	    <joint name="cable_4e" type="hinge" pos="-0.115 0.09 0.1625"/>	    
　　</body>

    	<body name="x2" pos="-0.45 -0.35 2.52" childclass="x2">

	      <camera name="track" pos="-1 0 .5" xyaxes="0 -1 0 1 0 2" mode="trackcom"/>
	      <site name="imu" pos="0 0 .02"/>
	      <joint name="cable_1s" type="hinge" pos="0 0 .0"/>
	      
	      <geom material="phong3SG" mesh="X2_lowpoly" class="visual" quat="0 0 1 1"/>
	      <geom class="collision" size=".06 .027 .02" pos=".04 0 .02"/>
	      <geom class="collision" size=".06 .027 .02" pos=".04 0 .06"/>
	      <geom class="collision" size=".05 .027 .02" pos="-.07 0 .065"/>
	      <geom class="collision" size=".023 .017 .01" pos="-.137 .008 .065" quat="1 0 0 1"/>
	      <geom name="rotor1" class="rotor" pos="-.275 -.275 .05" mass=".29175"/>
	      <geom name="rotor2" class="rotor" pos="-.275 .275 .05" mass=".29175"/>
	      <geom name="rotor3" class="rotor" pos=".275 .275 .08" mass=".29175"/>
	      <geom name="rotor4" class="rotor" pos=".275 -.275 .08" mass=".29175"/>
	      <geom size=".16 .04 .02" pos="0 0 0.02" type="ellipsoid" mass=".115" class="visual" material="invisible"/>
	      <site name="thrust1" pos="-.14 -.18 .05"/>
	      <site name="thrust2" pos="-.14 .18 .05"/>
	      <site name="thrust3" pos=".14 .18 .08"/>
	      <site name="thrust4" pos=".14 -.18 .08"/>


      </body>



    	<body name="x2_1" pos="0.45 -0.35 2.52" childclass="x2">
	      
	      <camera name="track_1" pos="-1 0 .5" xyaxes="0 -1 0 1 0 2" mode="trackcom"/>
	      <site name="imu_1" pos="1 0 .02"/>
	      <joint name="cable_2s" type="hinge" pos="0 0 .0"/>
	      
	      <geom material="phong3SG" mesh="X2_lowpoly" class="visual" quat="0 0 1 1"/>
	      <geom class="collision" size=".06 .027 .02" pos=".04 0 .02"/>
	      <geom class="collision" size=".06 .027 .02" pos=".04 0 .06"/>
	      <geom class="collision" size=".05 .027 .02" pos="-.07 0 .065"/>
	      <geom class="collision" size=".023 .017 .01" pos="-.137 .008 .065" quat="1 0 0 1"/>
	      <geom name="rotor1_1" class="rotor" pos="-.275 -.275 .05" mass=".29175"/>
	      <geom name="rotor2_1" class="rotor" pos="-.275 .275 .05" mass=".29175"/>
	      <geom name="rotor3_1" class="rotor" pos=".275 .275 .08" mass=".29175"/>
	      <geom name="rotor4_1" class="rotor" pos=".275 -.275 .08" mass=".29175"/>
	      <geom size=".16 .04 .02" pos="0 0 0.02" type="ellipsoid" mass=".115" class="visual" material="invisible"/>
	      <site name="thrust1_1" pos="-.14 -.18 .05"/>
	      <site name="thrust2_1" pos="-.14 .18 .05"/>
	      <site name="thrust3_1" pos=".14 .18 .08"/>
	      <site name="thrust4_1" pos=".14 -.18 .08"/>


      </body>
      
      <body name="x2_2" pos="0.45 0.35 2.52" childclass="x2">
	    
	      <camera name="track_2" pos="-1 0 .5" xyaxes="0 -1 0 1 0 2" mode="trackcom"/>
	      <site name="imu_2" pos="1 0 .02"/>
	      <joint name="cable_3s" type="hinge" pos="0 0 .0"/>
	      <geom material="phong3SG" mesh="X2_lowpoly" class="visual" quat="0 0 1 1"/>
	      <geom class="collision" size=".06 .027 .02" pos=".04 0 .02"/>
	      <geom class="collision" size=".06 .027 .02" pos=".04 0 .06"/>
	      <geom class="collision" size=".05 .027 .02" pos="-.07 0 .065"/>
	      <geom class="collision" size=".023 .017 .01" pos="-.137 .008 .065" quat="1 0 0 1"/>
	      <geom name="rotor1_2" class="rotor" pos="-.275 -.275 .05" mass=".29175"/>
	      <geom name="rotor2_2" class="rotor" pos="-.275 .275 .05" mass=".29175"/>
	      <geom name="rotor3_2" class="rotor" pos=".275 .275 .08" mass=".29175"/>
	      <geom name="rotor4_2" class="rotor" pos=".275 -.275 .08" mass=".29175"/>
	      <geom size=".16 .04 .02" pos="0 0 0.02" type="ellipsoid" mass=".115" class="visual" material="invisible"/>
	      <site name="thrust1_2" pos="-.14 -.18 .05"/>
	      <site name="thrust2_2" pos="-.14 .18 .05"/>
	      <site name="thrust3_2" pos=".14 .18 .08"/>
	      <site name="thrust4_2" pos=".14 -.18 .08"/>



      
      </body>
      
      <body name="x2_3" pos="-0.45 0.35 2.52" childclass="x2">
	    
	      <camera name="track_3" pos="-1 0 .5" xyaxes="0 -1 0 1 0 2" mode="trackcom"/>
	      <site name="imu_3" pos="1 0 .02"/>
	      <joint name="cable_4s" type="hinge" pos="0 0 .0"/>
	      
	      <geom material="phong3SG" mesh="X2_lowpoly" class="visual" quat="0 0 1 1"/>
	      <geom class="collision" size=".06 .027 .02" pos=".04 0 .02"/>
	      <geom class="collision" size=".06 .027 .02" pos=".04 0 .06"/>
	      <geom class="collision" size=".05 .027 .02" pos="-.07 0 .065"/>
	      <geom class="collision" size=".023 .017 .01" pos="-.137 .008 .065" quat="1 0 0 1"/>
	      <geom name="rotor1_3" class="rotor" pos="-.275 -.275 .05" mass=".29175"/>
	      <geom name="rotor2_3" class="rotor" pos="-.275 .275 .05" mass=".29175"/>
	      <geom name="rotor3_3" class="rotor" pos=".275 .275 .08" mass=".29175"/>
	      <geom name="rotor4_3" class="rotor" pos=".275 -.275 .08" mass=".29175"/>
	      <geom size=".16 .04 .02" pos="0 0 0.02" type="ellipsoid" mass=".115" class="visual" material="invisible"/>
	      <site name="thrust1_3" pos="-.14 -.18 .05"/>
	      <site name="thrust2_3" pos="-.14 .18 .05"/>
	      <site name="thrust3_3" pos=".14 .18 .08"/>
	      <site name="thrust4_3" pos=".14 -.18 .08"/>



     </body>

  </worldbody>

  <actuator>
    <motor class="x2" name="thrust1" site="thrust1" gear="0 0 1 0 0 .0201"/>
    <motor class="x2" name="thrust2" site="thrust2" gear="0 0 1 0 0 -.0201"/>
    <motor class="x2" name="thrust3" site="thrust3" gear="0 0 1 0 0 .0201"/>
    <motor class="x2" name="thrust4" site="thrust4" gear="0 0 1 0 0 -.0201"/>
    
    <motor class="x2" name="thrust1_1" site="thrust1_1" gear="0 0 1 0 0 .0201"/>
    <motor class="x2" name="thrust2_1" site="thrust2_1" gear="0 0 1 0 0 -.0201"/>
    <motor class="x2" name="thrust3_1" site="thrust3_1" gear="0 0 1 0 0 .0201"/>
    <motor class="x2" name="thrust4_1" site="thrust4_1" gear="0 0 1 0 0 -.0201"/>
    
    <motor class="x2" name="thrust1_2" site="thrust1_2" gear="0 0 1 0 0 .0201"/>
    <motor class="x2" name="thrust2_2" site="thrust2_2" gear="0 0 1 0 0 -.0201"/>
    <motor class="x2" name="thrust3_2" site="thrust3_2" gear="0 0 1 0 0 .0201"/>
    <motor class="x2" name="thrust4_2" site="thrust4_2" gear="0 0 1 0 0 -.0201"/>
    
    <motor class="x2" name="thrust1_3" site="thrust1_3" gear="0 0 1 0 0 .0201"/>
    <motor class="x2" name="thrust2_3" site="thrust2_3" gear="0 0 1 0 0 -.0201"/>
    <motor class="x2" name="thrust3_3" site="thrust3_3" gear="0 0 1 0 0 .0201"/>
    <motor class="x2" name="thrust4_3" site="thrust4_3" gear="0 0 1 0 0 -.0201"/>
  </actuator>

  <sensor>
  
    <gyro name="body_gyro" site="imu"/>
    <accelerometer name="body_linacc" site="imu"/>
    <framequat name="body_quat" objtype="site" objname="imu"/>
    
    <gyro name="body_gyro_1" site="imu_1"/>
    <accelerometer name="body_linacc_1" site="imu_1"/>
    <framequat name="body_quat_1" objtype="site" objname="imu_1"/>
    
    <gyro name="body_gyro_2" site="imu_2"/>
    <accelerometer name="body_linacc_2" site="imu_2"/>
    <framequat name="body_quat_2" objtype="site" objname="imu_2"/>
    
    <gyro name="body_gyro_3" site="imu_3"/>
    <accelerometer name="body_linacc_3" site="imu_3"/>
    <framequat name="body_quat_3" objtype="site" objname="imu_3"/>
  </sensor>


<tendon>
	    <fixed name="s1" >
		    <joint joint="cable_1e" coef="1.0"/>
		    <joint joint="cable_1s" coef="-1.0"/>
	    </fixed>
	    <fixed name="s2">
		    <joint joint="cable_2e" coef="1.0"/>
		    <joint joint="cable_2s" coef="-1.0"/>
	    </fixed>
	    <fixed name="s3">
		    <joint joint="cable_3e" coef="1.0"/>
		    <joint joint="cable_3s" coef="-1.0"/>
	    </fixed>
	    <fixed name="s4">
		    <joint joint="cable_4e" coef="1.0"/>
		    <joint joint="cable_4s" coef="-1.0"/>
	    </fixed>
</tendon>



  <!-- <keyframe>
    <key name="hover" qpos="0 0 .3 1 0 0 0" ctrl="3.2495625 3.2495625 3.2495625 3.2495625"/>
  </keyframe> -->
</mujoco>
